<?xml version="1.0" encoding="utf-8"?>
<robot
  name="humanoid">
  <link
    name="base_link">
    <inertial>
      <origin
        xyz="1.07784451355147E-06 0.0284280497758001 0.0930501056429116"
        rpy="0 0 0" />
      <mass
        value="25.2827775843096" />
      <inertia
        ixx="1.05306308303982"
        ixy="5.35850857338871E-07"
        ixz="-8.40544864225828E-06"
        iyy="0.379347819173407"
        iyz="4.4668154477851E-06"
        izz="1.39119566760917" />
    </inertial>
    <visual>
      <origin
        xyz="0 0 0"
        rpy="0 0 0" />
      <geometry>
        <mesh
          filename="package://robot_description/meshes/base_link.STL" />
      </geometry>
      <material
        name="">
        <color
          rgba="0.792156862745098 0.819607843137255 0.929411764705882 1" />
      </material>
    </visual>
    <collision>
      <origin
        xyz="0 0 0"
        rpy="0 0 0" />
      <geometry>
        <mesh
          filename="package://robot_description/meshes/base_link.STL" />
      </geometry>
    </collision>
  </link>
  <link
    name="neck_pitch_link">
    <inertial>
      <origin
        xyz="7.01840304657472E-05 0.130777470021731 -0.00331694653990108"
        rpy="0 0 0" />
      <mass
        value="0.148218827310183" />
      <inertia
        ixx="9.52279837773781E-05"
        ixy="-9.91190135430179E-08"
        ixz="1.98844059206848E-07"
        iyy="7.30070921223501E-05"
        iyz="3.47609457314995E-06"
        izz="9.0131560532935E-05" />
    </inertial>
    <visual>
      <origin
        xyz="0 0 0"
        rpy="0 0 0" />
      <geometry>
        <mesh
          filename="package://robot_description/meshes/neck_pitch_link.STL" />
      </geometry>
      <material
        name="">
        <color
          rgba="0.647058823529412 0.619607843137255 0.588235294117647 1" />
      </material>
    </visual>
    <collision>
      <origin
        xyz="0 0 0"
        rpy="0 0 0" />
      <geometry>
        <mesh
          filename="package://robot_description/meshes/neck_pitch_link.STL" />
      </geometry>
    </collision>
  </link>
  <joint
    name="neck_pitch_joint"
    type="revolute">
    <origin
      xyz="0 0.189998253900838 0.835499049600994"
      rpy="1.5707963267949 0 1.5707963267949" />
    <parent
      link="base_link" />
    <child
      link="neck_pitch_link" />
    <axis
      xyz="0 1 0" />
    <limit
      lower="-3.14"
      upper="3.14"
      effort="20"
      velocity="50" />
  </joint>
  <link
    name="neck_yaw_link">
    <inertial>
      <origin
        xyz="-0.00016459752079714 0.00712784323803106 -0.0394648436747978"
        rpy="0 0 0" />
      <mass
        value="0.0765456211575113" />
      <inertia
        ixx="3.23897327523942E-05"
        ixy="-2.65902764441305E-14"
        ixz="-5.98960713926039E-15"
        iyy="1.63880392625728E-05"
        iyz="5.16658827031463E-07"
        izz="4.47591140398881E-05" />
    </inertial>
    <visual>
      <origin
        xyz="0 0 0"
        rpy="0 0 0" />
      <geometry>
        <mesh
          filename="package://robot_description/meshes/neck_yaw_link.STL" />
      </geometry>
      <material
        name="">
        <color
          rgba="1 1 1 0.25" />
      </material>
    </visual>
    <collision>
      <origin
        xyz="0 0 0"
        rpy="0 0 0" />
      <geometry>
        <mesh
          filename="package://robot_description/meshes/neck_yaw_link.STL" />
      </geometry>
    </collision>
  </link>
  <joint
    name="neck_yaw_joint"
    type="revolute">
    <origin
      xyz="0.000164597494633156 0.135935192091684 0.0268002104136432"
      rpy="0 0 0" />
    <parent
      link="neck_pitch_link" />
    <child
      link="neck_yaw_link" />
    <axis
      xyz="0 0 1" />
    <limit
      lower="-3.14"
      upper="3.14"
      effort="20"
      velocity="50" />
  </joint>
  <link
    name="head_camera_link">
    <inertial>
      <origin
        xyz="-0.0538137633177245 4.16333634234434E-17 0"
        rpy="0 0 0" />
      <mass
        value="0.398240212565594" />
      <inertia
        ixx="0.00225801965865169"
        ixy="3.25260651745651E-19"
        ixz="2.29715335295366E-18"
        iyy="0.00143841223628256"
        iyz="-1.12485975395371E-18"
        izz="0.00239435389760271" />
    </inertial>
    <visual>
      <origin
        xyz="0 0 0"
        rpy="0 0 0" />
      <geometry>
        <mesh
          filename="package://robot_description/meshes/head_camera_link.STL" />
      </geometry>
      <material
        name="">
        <color
          rgba="1 1 1 1" />
      </material>
    </visual>
    <collision>
      <origin
        xyz="0 0 0"
        rpy="0 0 0" />
      <geometry>
        <mesh
          filename="package://robot_description/meshes/head_camera_link.STL" />
      </geometry>
    </collision>
  </link>
  <joint
    name="head_camera_joint"
    type="fixed">
    <origin
      xyz="0.0498354025053677 0.109164807908296 -0.0267999999999801"
      rpy="-1.5707963267949 0 0" />
    <parent
      link="neck_yaw_link" />
    <child
      link="head_camera_link" />
  </joint>
  <link
    name="right_base_pitch_link">
    <inertial>
      <origin
        xyz="-0.0394540906091678 -0.00117049156839028 0.0362772096702395"
        rpy="0 0 0" />
      <mass
        value="0.244817289982652" />
      <inertia
        ixx="0.00042258611468929"
        ixy="-3.33213778042763E-07"
        ixz="6.13148868322963E-05"
        iyy="0.00043362815715413"
        iyz="1.84861840406614E-06"
        izz="0.000449580199614448" />
    </inertial>
    <visual>
      <origin
        xyz="0 0 0"
        rpy="0 0 0" />
      <geometry>
        <mesh
          filename="package://robot_description/meshes/right_base_pitch_link.STL" />
      </geometry>
      <material
        name="">
        <color
          rgba="1 1 1 1" />
      </material>
    </visual>
    <collision>
      <origin
        xyz="0 0 0"
        rpy="0 0 0" />
      <geometry>
        <mesh
          filename="package://robot_description/meshes/right_base_pitch_link.STL" />
      </geometry>
    </collision>
  </link>
  <joint
    name="right_base_pitch_joint"
    type="revolute">
    <origin
      xyz="0.21400441954841 0.189998253900819 0.822999049601032"
      rpy="1.5707963267949 0 1.5707963267949" />
    <parent
      link="base_link" />
    <child
      link="right_base_pitch_link" />
    <axis
      xyz="0 0 -1" />
    <limit
      lower="-3.14"
      upper="3.14"
      effort="20"
      velocity="50" />
  </joint>
  <link
    name="right_shoulder_roll_link">
    <inertial>
      <origin
        xyz="-0.0504751969032359 -2.3505993093087E-06 -0.0382593125478601"
        rpy="0 0 0" />
      <mass
        value="0.219562602027133" />
      <inertia
        ixx="0.000414250305228579"
        ixy="-5.1544201930132E-09"
        ixz="-8.79018796006794E-05"
        iyy="0.000412104091228023"
        iyz="-6.24422590434745E-08"
        izz="0.000365288665382115" />
    </inertial>
    <visual>
      <origin
        xyz="0 0 0"
        rpy="0 0 0" />
      <geometry>
        <mesh
          filename="package://robot_description/meshes/right_shoulder_roll_link.STL" />
      </geometry>
      <material
        name="">
        <color
          rgba="1 1 1 1" />
      </material>
    </visual>
    <collision>
      <origin
        xyz="0 0 0"
        rpy="0 0 0" />
      <geometry>
        <mesh
          filename="package://robot_description/meshes/right_shoulder_roll_link.STL" />
      </geometry>
    </collision>
  </link>
  <joint
    name="right_shoulder_roll_joint"
    type="revolute">
    <origin
      xyz="0.0512767086241353 0.00154568843845215 0.070000086877735"
      rpy="1.57079632679489 -0.0124370994640314 1.60093654227117" />
    <parent
      link="right_base_pitch_link" />
    <child
      link="right_shoulder_roll_link" />
    <axis
      xyz="0 0 -1" />
    <limit
      lower="-3.14"
      upper="3.14"
      effort="20"
      velocity="50" />
  </joint>
  <link
    name="right_shoulder_yaw_link">
    <inertial>
      <origin
        xyz="-0.020385273211367 -8.15235141520682E-06 0.0357353445479509"
        rpy="0 0 0" />
      <mass
        value="0.106143604615312" />
      <inertia
        ixx="9.66386839936161E-05"
        ixy="-4.74531869270227E-09"
        ixz="2.12882628388833E-05"
        iyy="0.000122064598284769"
        iyz="-6.1579299009481E-08"
        izz="0.00010313012003071" />
    </inertial>
    <visual>
      <origin
        xyz="0 0 0"
        rpy="0 0 0" />
      <geometry>
        <mesh
          filename="package://robot_description/meshes/right_shoulder_yaw_link.STL" />
      </geometry>
      <material
        name="">
        <color
          rgba="1 1 1 1" />
      </material>
    </visual>
    <collision>
      <origin
        xyz="0 0 0"
        rpy="0 0 0" />
      <geometry>
        <mesh
          filename="package://robot_description/meshes/right_shoulder_yaw_link.STL" />
      </geometry>
    </collision>
  </link>
  <joint
    name="right_shoulder_yaw_joint"
    type="revolute">
    <origin
      xyz="-0.161499730454391 0 -0.0674997882054564"
      rpy="1.5707963267949 -0.209915812016821 -1.5707963267949" />
    <parent
      link="right_shoulder_roll_link" />
    <child
      link="right_shoulder_yaw_link" />
    <axis
      xyz="0 0 1" />
    <limit
      lower="-3.14"
      upper="3.14"
      effort="20"
      velocity="50" />
  </joint>
  <link
    name="right_elbow_pitch_link">
    <inertial>
      <origin
        xyz="-3.42841572391756E-05 0.0729459113904672 -0.0410111671034344"
        rpy="0 0 0" />
      <mass
        value="0.154099206711241" />
      <inertia
        ixx="8.75612800169932E-05"
        ixy="-8.24914993394397E-08"
        ixz="2.8611763084907E-08"
        iyy="8.00343513136428E-05"
        iyz="9.62612120488893E-06"
        izz="7.60282435942892E-05" />
    </inertial>
    <visual>
      <origin
        xyz="0 0 0"
        rpy="0 0 0" />
      <geometry>
        <mesh
          filename="package://robot_description/meshes/right_elbow_pitch_link.STL" />
      </geometry>
      <material
        name="">
        <color
          rgba="1 1 1 1" />
      </material>
    </visual>
    <collision>
      <origin
        xyz="0 0 0"
        rpy="0 0 0" />
      <geometry>
        <mesh
          filename="package://robot_description/meshes/right_elbow_pitch_link.STL" />
      </geometry>
    </collision>
  </link>
  <joint
    name="right_elbow_pitch_joint"
    type="revolute">
    <origin
      xyz="0.0495000377373268 0 0.0624999168897828"
      rpy="1.5707963267949 0.00263601886731738 1.5707963267949" />
    <parent
      link="right_shoulder_yaw_link" />
    <child
      link="right_elbow_pitch_link" />
    <axis
      xyz="-0.333848242516012 0.0592718558412337 0.940761499039" />
    <limit
      lower="-3.14"
      upper="3.14"
      effort="20"
      velocity="50" />
  </joint>
  <link
    name="right_wrist_pitch_link">
    <inertial>
      <origin
        xyz="2.75788182445003E-05 -0.000871878112892799 0.104186529687359"
        rpy="0 0 0" />
      <mass
        value="0.192205595442942" />
      <inertia
        ixx="0.000302459654412395"
        ixy="8.24266800328281E-08"
        ixz="2.75449341259816E-08"
        iyy="0.00028537077989617"
        iyz="3.77471294040012E-05"
        izz="9.91159076780823E-05" />
    </inertial>
    <visual>
      <origin
        xyz="0 0 0"
        rpy="0 0 0" />
      <geometry>
        <mesh
          filename="package://robot_description/meshes/right_wrist_pitch_link.STL" />
      </geometry>
      <material
        name="">
        <color
          rgba="1 1 1 1" />
      </material>
    </visual>
    <collision>
      <origin
        xyz="0 0 0"
        rpy="0 0 0" />
      <geometry>
        <mesh
          filename="package://robot_description/meshes/right_wrist_pitch_link.STL" />
      </geometry>
    </collision>
  </link>
  <joint
    name="right_wrist_pitch_joint"
    type="revolute">
    <origin
      xyz="0 0.126500083668823 -0.0495002104136634"
      rpy="1.5707963267949 0.208003209624867 3.14159265358979" />
    <parent
      link="right_elbow_pitch_link" />
    <child
      link="right_wrist_pitch_link" />
    <axis
      xyz="0 0 -1" />
    <limit
      lower="-3.14"
      upper="3.14"
      effort="20"
      velocity="50" />
  </joint>
  <link
    name="right_wrist_yaw_link">
    <inertial>
      <origin
        xyz="7.27612933126079E-05 0.0809191230537369 -0.0386606819862753"
        rpy="0 0 0" />
      <mass
        value="0.175438598998815" />
      <inertia
        ixx="9.6324565447174E-05"
        ixy="1.37624512021152E-07"
        ixz="2.89958169269242E-06"
        iyy="0.000109953050418614"
        iyz="5.03326002219079E-06"
        izz="0.000125124839716495" />
    </inertial>
    <visual>
      <origin
        xyz="0 0 0"
        rpy="0 0 0" />
      <geometry>
        <mesh
          filename="package://robot_description/meshes/right_wrist_yaw_link.STL" />
      </geometry>
      <material
        name="">
        <color
          rgba="1 1 1 1" />
      </material>
    </visual>
    <collision>
      <origin
        xyz="0 0 0"
        rpy="0 0 0" />
      <geometry>
        <mesh
          filename="package://robot_description/meshes/right_wrist_yaw_link.STL" />
      </geometry>
    </collision>
  </link>
  <joint
    name="right_wrist_yaw_joint"
    type="revolute">
    <origin
      xyz="0 0.0414999999999797 0.140500210413661"
      rpy="1.5707963267949 0.575197538261195 3.14159265358979" />
    <parent
      link="right_wrist_pitch_link" />
    <child
      link="right_wrist_yaw_link" />
    <axis
      xyz="0 0 -1" />
    <limit
      lower="-3.14"
      upper="3.14"
      effort="20"
      velocity="50" />
  </joint>
  <link
    name="right_gripper1_link">
    <inertial>
      <origin
        xyz="-0.0594271349448385 -0.0021592700647648 0.0242071304277063"
        rpy="0 0 0" />
      <mass
        value="0.0358339207664623" />
      <inertia
        ixx="1.96900849491953E-05"
        ixy="1.49577745788164E-07"
        ixz="-2.61611297419697E-06"
        iyy="1.51820051704718E-05"
        iyz="4.68868627254808E-07"
        izz="8.95629031357462E-06" />
    </inertial>
    <visual>
      <origin
        xyz="0 0 0"
        rpy="0 0 0" />
      <geometry>
        <mesh
          filename="package://robot_description/meshes/right_gripper1_link.STL" />
      </geometry>
      <material
        name="">
        <color
          rgba="0.0980392156862745 0.0980392156862745 0.0980392156862745 1" />
      </material>
    </visual>
    <collision>
      <origin
        xyz="0 0 0"
        rpy="0 0 0" />
      <geometry>
        <mesh
          filename="package://robot_description/meshes/right_gripper1_link.STL" />
      </geometry>
    </collision>
  </link>
  <joint
    name="right_gripper1_joint"
    type="prismatic">
    <origin
      xyz="0 0.141000000000003 -0.0424999999999999"
      rpy="1.5707963267949 0 3.14159265358979" />
    <parent
      link="right_wrist_yaw_link" />
    <child
      link="right_gripper1_link" />
    <axis
      xyz="1 0 0" />
    <limit
      lower="0"
      upper="0.03"
      effort="20"
      velocity="50" />
  </joint>
  <link
    name="right_gripper2_link">
    <inertial>
      <origin
        xyz="0.0596503865175193 0.0019659579201895 0.0221271099610874"
        rpy="0 0 0" />
      <mass
        value="0.0393551869062514" />
      <inertia
        ixx="1.98397159910276E-05"
        ixy="1.49583238832345E-07"
        ixz="2.6160400152461E-06"
        iyy="1.54499686755966E-05"
        iyz="-4.68723727640429E-07"
        izz="9.3435573957773E-06" />
    </inertial>
    <visual>
      <origin
        xyz="0 0 0"
        rpy="0 0 0" />
      <geometry>
        <mesh
          filename="package://robot_description/meshes/right_gripper2_link.STL" />
      </geometry>
      <material
        name="">
        <color
          rgba="0.0980392156862745 0.0980392156862745 0.0980392156862745 1" />
      </material>
    </visual>
    <collision>
      <origin
        xyz="0 0 0"
        rpy="0 0 0" />
      <geometry>
        <mesh
          filename="package://robot_description/meshes/right_gripper2_link.STL" />
      </geometry>
    </collision>
  </link>
  <joint
    name="right_gripper2_joint"
    type="prismatic">
    <origin
      xyz="0 0.141000000000003 -0.0424999999999999"
      rpy="1.5707963267949 0 3.14159265358979" />
    <parent
      link="right_wrist_yaw_link" />
    <child
      link="right_gripper2_link" />
    <axis
      xyz="1 0 0" />
    <mimic joint="right_gripper1_joint" multiplier="-1.0" />
    <limit
      lower="-0.03"
      upper="0"
      effort="20"
      velocity="50" />
  </joint>
  <link
    name="right_camera_link">
    <inertial>
      <origin
        xyz="-0.0114169669754792 0.0212636187934237 2.88094353928514E-09"
        rpy="0 0 0" />
      <mass
        value="0.0226998455840004" />
      <inertia
        ixx="2.58527414343368E-05"
        ixy="1.1600323718797E-06"
        ixz="4.88501458827519E-13"
        iyy="2.38075275750142E-06"
        iyz="-3.21125084462628E-12"
        izz="2.45019772015967E-05" />
    </inertial>
    <visual>
      <origin
        xyz="0 0 0"
        rpy="0 0 0" />
      <geometry>
        <mesh
          filename="package://robot_description/meshes/right_camera_link.STL" />
      </geometry>
      <material
        name="">
        <color
          rgba="1 1 1 1" />
      </material>
    </visual>
    <collision>
      <origin
        xyz="0 0 0"
        rpy="0 0 0" />
      <geometry>
        <mesh
          filename="package://robot_description/meshes/right_camera_link.STL" />
      </geometry>
    </collision>
  </link>
  <joint
    name="right_camera_joint"
    type="fixed">
    <origin
      xyz="0.000000000 0.072000210 -0.156500000"
      rpy="1.570796327 0.000000000 1.570796327" />
    <parent
      link="right_wrist_yaw_link" />
    <child
      link="right_camera_link" />
  </joint>
  <link
    name="left_base_pitch_link">
    <inertial>
      <origin
        xyz="-0.03944182710006 -0.00152845155914194 0.0362690454576601"
        rpy="0 0 0" />
      <mass
        value="0.244817361510199" />
      <inertia
        ixx="0.000422591073242316"
        ixy="-3.83795654275043E-07"
        ixz="6.13829987729351E-05"
        iyy="0.000432397607788544"
        iyz="1.68051540593824E-07"
        izz="0.000450805804784789" />
    </inertial>
    <visual>
      <origin
        xyz="0 0 0"
        rpy="0 0 0" />
      <geometry>
        <mesh
          filename="package://robot_description/meshes/left_base_pitch_link.STL" />
      </geometry>
      <material
        name="">
        <color
          rgba="1 1 1 1" />
      </material>
    </visual>
    <collision>
      <origin
        xyz="0 0 0"
        rpy="0 0 0" />
      <geometry>
        <mesh
          filename="package://robot_description/meshes/left_base_pitch_link.STL" />
      </geometry>
    </collision>
  </link>
  <joint
    name="left_base_pitch_joint"
    type="revolute">
    <origin
      xyz="-0.213995580451608 0.18999825390085 0.822999049601032"
      rpy="-1.5707963267949 0 1.5707963267949" />
    <parent
      link="base_link" />
    <child
      link="left_base_pitch_link" />
    <axis
      xyz="0 0 1" />
    <limit
      lower="-3.14"
      upper="3.14"
      effort="20"
      velocity="50" />
  </joint>
  <link
    name="left_shoulder_roll_link">
    <inertial>
      <origin
        xyz="0.0504756732403198 -2.46635897149794E-06 -0.0382670921109684"
        rpy="0 0 0" />
      <mass
        value="0.219562602025694" />
      <inertia
        ixx="0.000414250305226946"
        ixy="5.14066613970505E-09"
        ixz="8.78921299241681E-05"
        iyy="0.000412104442343155"
        iyz="6.2007231242088E-08"
        izz="0.00036528831426658" />
    </inertial>
    <visual>
      <origin
        xyz="0 0 0"
        rpy="0 0 0" />
      <geometry>
        <mesh
          filename="package://robot_description/meshes/left_shoulder_roll_link.STL" />
      </geometry>
      <material
        name="">
        <color
          rgba="1 1 1 1" />
      </material>
    </visual>
    <collision>
      <origin
        xyz="0 0 0"
        rpy="0 0 0" />
      <geometry>
        <mesh
          filename="package://robot_description/meshes/left_shoulder_roll_link.STL" />
      </geometry>
    </collision>
  </link>
  <joint
    name="left_shoulder_roll_joint"
    type="revolute">
    <origin
      xyz="0.0512608845048458 0.00200292781174632 0.0700002065331428"
      rpy="1.5707963267949 0.0572282794585209 1.6098534872918" />
    <parent
      link="left_base_pitch_link" />
    <child
      link="left_shoulder_roll_link" />
    <axis
      xyz="0 0 1" />
    <limit
      lower="-3.14"
      upper="3.14"
      effort="20"
      velocity="50" />
  </joint>
  <link
    name="left_shoulder_yaw_link">
    <inertial>
      <origin
        xyz="0.0203852048517859 3.01779778964784E-06 0.0387394862827194"
        rpy="0 0 0" />
      <mass
        value="0.106143599746768" />
      <inertia
        ixx="9.66386800285855E-05"
        ixy="-6.92480790310884E-09"
        ixz="-2.1292772309331E-05"
        iyy="0.00012207057327241"
        iyz="-6.92239720606759E-08"
        izz="0.00010312414056542" />
    </inertial>
    <visual>
      <origin
        xyz="0 0 0"
        rpy="0 0 0" />
      <geometry>
        <mesh
          filename="package://robot_description/meshes/left_shoulder_yaw_link.STL" />
      </geometry>
      <material
        name="">
        <color
          rgba="1 1 1 1" />
      </material>
    </visual>
    <collision>
      <origin
        xyz="0 0 0"
        rpy="0 0 0" />
      <geometry>
        <mesh
          filename="package://robot_description/meshes/left_shoulder_yaw_link.STL" />
      </geometry>
    </collision>
  </link>
  <joint
    name="left_shoulder_yaw_joint"
    type="revolute">
    <origin
      xyz="0.161500206792132 0 -0.0675002120298684"
      rpy="1.5707963267949 0.127054181766171 1.5707963267949" />
    <parent
      link="left_shoulder_roll_link" />
    <child
      link="left_shoulder_yaw_link" />
    <axis
      xyz="0 0 1" />
    <limit
      lower="-3.14"
      upper="3.14"
      effort="20"
      velocity="50" />
  </joint>
  <link
    name="left_elbow_pitch_link">
    <inertial>
      <origin
        xyz="7.07768641869111E-05 0.0729456723984567 -0.0410914590768398"
        rpy="0 0 0" />
      <mass
        value="0.154099169383945" />
      <inertia
        ixx="8.74785494949814E-05"
        ixy="2.61941007548108E-07"
        ixz="4.53756275437878E-08"
        iyy="8.00343035751047E-05"
        iyz="9.22673260793295E-06"
        izz="7.61109498248455E-05" />
    </inertial>
    <visual>
      <origin
        xyz="0 0 0"
        rpy="0 0 0" />
      <geometry>
        <mesh
          filename="package://robot_description/meshes/left_elbow_pitch_link.STL" />
      </geometry>
      <material
        name="">
        <color
          rgba="1 1 1 1" />
      </material>
    </visual>
    <collision>
      <origin
        xyz="0 0 0"
        rpy="0 0 0" />
      <geometry>
        <mesh
          filename="package://robot_description/meshes/left_elbow_pitch_link.STL" />
      </geometry>
    </collision>
  </link>
  <joint
    name="left_elbow_pitch_joint"
    type="revolute">
    <origin
      xyz="-0.0495001093071362 0 0.0655000777356621"
      rpy="1.5707963267949 -0.456186992961128 -1.5707963267949" />
    <parent
      link="left_shoulder_yaw_link" />
    <child
      link="left_elbow_pitch_link" />
    <axis
      xyz="0 0 1" />
    <limit
      lower="-3.14"
      upper="3.14"
      effort="20"
      velocity="50" />
  </joint>
  <link
    name="left_wrist_pitch_link">
    <inertial>
      <origin
        xyz="-4.68439746814861E-05 -0.000871876921878401 0.104203137099242"
        rpy="0 0 0" />
      <mass
        value="0.192205491051058" />
      <inertia
        ixx="0.000302371428903046"
        ixy="-2.63172936807209E-07"
        ixz="-4.15138144826291E-08"
        iyy="0.000285370627704525"
        iyz="3.79042961472345E-05"
        izz="9.92039705376368E-05" />
    </inertial>
    <visual>
      <origin
        xyz="0 0 0"
        rpy="0 0 0" />
      <geometry>
        <mesh
          filename="package://robot_description/meshes/left_wrist_pitch_link.STL" />
      </geometry>
      <material
        name="">
        <color
          rgba="1 1 1 1" />
      </material>
    </visual>
    <collision>
      <origin
        xyz="0 0 0"
        rpy="0 0 0" />
      <geometry>
        <mesh
          filename="package://robot_description/meshes/left_wrist_pitch_link.STL" />
      </geometry>
    </collision>
  </link>
  <joint
    name="left_wrist_pitch_joint"
    type="revolute">
    <origin
      xyz="0 0.126499835914674 -0.0494999999999997"
      rpy="1.5707963267949 -0.171337297578539 -3.14159265358979" />
    <parent
      link="left_elbow_pitch_link" />
    <child
      link="left_wrist_pitch_link" />
    <axis
      xyz="0 0 1" />
    <limit
      lower="-3.14"
      upper="3.14"
      effort="20"
      velocity="50" />
  </joint>
  <link
    name="left_wrist_yaw_link">
    <inertial>
      <origin
        xyz="1.8321381735055E-05 0.080809432361566 -0.0385984001620683"
        rpy="0 0 0" />
      <mass
        value="0.175099344991619" />
      <inertia
        ixx="9.63204266828382E-05"
        ixy="1.37572954355653E-07"
        ixz="2.8996374938886E-06"
        iyy="0.000109945415386354"
        iyz="5.03325452482642E-06"
        izz="0.000125120516099222" />
    </inertial>
    <visual>
      <origin
        xyz="0 0 0"
        rpy="0 0 0" />
      <geometry>
        <mesh
          filename="package://robot_description/meshes/left_wrist_yaw_link.STL" />
      </geometry>
      <material
        name="">
        <color
          rgba="1 1 1 1" />
      </material>
    </visual>
    <collision>
      <origin
        xyz="0 0 0"
        rpy="0 0 0" />
      <geometry>
        <mesh
          filename="package://robot_description/meshes/left_wrist_yaw_link.STL" />
      </geometry>
    </collision>
  </link>
  <joint
    name="left_wrist_yaw_joint"
    type="revolute">
    <origin
      xyz="0 0.0414999999999796 0.140500028913089"
      rpy="1.5707963267949 -0.0980347229909209 3.14159265358979" />
    <parent
      link="left_wrist_pitch_link" />
    <child
      link="left_wrist_yaw_link" />
    <axis
      xyz="0 0 -1" />
    <limit
      lower="-3.14"
      upper="3.14"
      effort="20"
      velocity="50" />
  </joint>
  <link
    name="left_gripper1_link">
    <inertial>
      <origin
        xyz="0.0593998317801899 0.00197506897058886 0.0245165047230118"
        rpy="0 0 0" />
      <mass
        value="0.0354364112817198" />
      <inertia
        ixx="1.96838533064286E-05"
        ixy="1.49528241959521E-07"
        ixz="2.61581514641577E-06"
        iyy="1.51756929438855E-05"
        iyz="-4.68756631362095E-07"
        izz="8.95265264035998E-06" />
    </inertial>
    <visual>
      <origin
        xyz="0 0 0"
        rpy="0 0 0" />
      <geometry>
        <mesh
          filename="package://robot_description/meshes/left_gripper1_link.STL" />
      </geometry>
      <material
        name="">
        <color
          rgba="0.0980392156862745 0.0980392156862745 0.0980392156862745 1" />
      </material>
    </visual>
    <collision>
      <origin
        xyz="0 0 0"
        rpy="0 0 0" />
      <geometry>
        <mesh
          filename="package://robot_description/meshes/left_gripper1_link.STL" />
      </geometry>
    </collision>
  </link>
  <joint
    name="left_gripper1_joint"
    type="prismatic">
    <origin
      xyz="0 0.14099995082628 -0.0425000000000004"
      rpy="1.5707963267949 0 -3.14159265358979" />
    <parent
      link="left_wrist_yaw_link" />
    <child
      link="left_gripper1_link" />
    <axis
      xyz="-1 0 0" />
    <limit
      lower="0"
      upper="0.03"
      effort="20"
      velocity="50" />
  </joint>
  <link
    name="left_gripper2_link">
    <inertial>
      <origin
        xyz="-0.0593992496111781 -0.00197501295200414 0.0245167055289283"
        rpy="0 0 0" />
      <mass
        value="0.0354366119716677" />
      <inertia
        ixx="1.96844205449425E-05"
        ixy="1.49584437236235E-07"
        ixz="-2.61603389629978E-06"
        iyy="1.51761628338051E-05"
        iyz="4.68724850359594E-07"
        izz="8.9529027072796E-06" />
    </inertial>
    <visual>
      <origin
        xyz="0 0 0"
        rpy="0 0 0" />
      <geometry>
        <mesh
          filename="package://robot_description/meshes/left_gripper2_link.STL" />
      </geometry>
      <material
        name="">
        <color
          rgba="0.0980392156862745 0.0980392156862745 0.0980392156862745 1" />
      </material>
    </visual>
    <collision>
      <origin
        xyz="0 0 0"
        rpy="0 0 0" />
      <geometry>
        <mesh
          filename="package://robot_description/meshes/left_gripper2_link.STL" />
      </geometry>
    </collision>
  </link>
  <joint
    name="left_gripper2_joint"
    type="prismatic">
    <origin
      xyz="0 0.14099995082628 -0.0425000000000004"
      rpy="1.5707963267949 0 -3.14159265358979" />
    <parent
      link="left_wrist_yaw_link" />
    <child
      link="left_gripper2_link" />
    <axis
      xyz="-1 0 0" />
    <mimic joint="left_gripper1_joint" multiplier="-1.0" />
    <limit
      lower="-0.03"
      upper="0"
      effort="20"
      velocity="50" />
  </joint>
  <link
    name="left_camera_link">
    <inertial>
      <origin
        xyz="-0.0114169668773913 2.94537169653886E-09 -0.0212636184254099"
        rpy="0 0 0" />
      <mass
        value="0.0226998454051643" />
      <inertia
        ixx="2.58527411194455E-05"
        ixy="4.96496635109783E-13"
        ixz="-1.16003231124756E-06"
        iyy="2.45019768869048E-05"
        iyz="3.29652727201937E-12"
        izz="2.38075273646055E-06" />
    </inertial>
    <visual>
      <origin
        xyz="0 0 0"
        rpy="0 0 0" />
      <geometry>
        <mesh
          filename="package://robot_description/meshes/left_camera_link.STL" />
      </geometry>
      <material
        name="">
        <color
          rgba="1 1 1 1" />
      </material>
    </visual>
    <collision>
      <origin
        xyz="0 0 0"
        rpy="0 0 0" />
      <geometry>
        <mesh
          filename="package://robot_description/meshes/left_camera_link.STL" />
      </geometry>
    </collision>
  </link>
  <joint
    name="left_camera_joint"
    type="fixed">
    <origin
      xyz="0.000000000 0.071999971 -0.156500000"
      rpy="-3.141592654 0.000000000 1.570796327" />
    <parent
      link="left_wrist_yaw_link" />
    <child
      link="left_camera_link" />
  </joint>
</robot>
