<?xml version="1.0" encoding="utf-8"?>
<robot
  name="humanoid">
  <link
    name="base_link">
    <inertial>
      <origin
        xyz="-0.176405742489603 1.56333797037868E-06 -0.717032572618786"
        rpy="0 0 0" />
      <mass
        value="25.8765862519602" />
      <inertia
        ixx="0.381071379447553"
        ixy="3.45647152318052E-06"
        ixz="3.8886722853633E-06"
        iyy="1.05471334674083"
        iyz="8.82057180130388E-06"
        izz="1.3942442215162" />
    </inertial>
    <visual>
      <origin
        xyz="0 0 0"
        rpy="0 0 0" />
      <geometry>
        <mesh
          filename="package://robot_description/meshes/base_link.STL" />
      </geometry>
      <material
        name="">
        <color
          rgba="1 1 1 1" />
      </material>
    </visual>
    <collision>
      <origin
        xyz="0 0 0"
        rpy="0 0 0" />
      <geometry>
        <mesh
          filename="package://robot_description/meshes/base_link.STL" />
      </geometry>
    </collision>
  </link>
  <link
    name="neck_pitch_link">
    <inertial>
      <origin
        xyz="-0.000451370404815097 0.102230180169134 0.0044792199154713"
        rpy="0 0 0" />
      <mass
        value="0.0471064788977039" />
      <inertia
        ixx="3.95125593138549E-05"
        ixy="-3.63724023459699E-07"
        ixz="1.35944347471052E-08"
        iyy="3.50656014386132E-05"
        iyz="-1.16677827059128E-06"
        izz="3.72317851569408E-05" />
    </inertial>
    <visual>
      <origin
        xyz="0 0 0"
        rpy="0 0 0" />
      <geometry>
        <mesh
          filename="package://robot_description/meshes/neck_pitch_link.STL" />
      </geometry>
      <material
        name="">
        <color
          rgba="1 1 1 0.25" />
      </material>
    </visual>
    <collision>
      <origin
        xyz="0 0 0"
        rpy="0 0 0" />
      <geometry>
        <mesh
          filename="package://robot_description/meshes/neck_pitch_link.STL" />
      </geometry>
    </collision>
  </link>
  <joint
    name="neck_pitch_joint"
    type="revolute">
    <origin
      xyz="0 0 0.0275"
      rpy="1.5708 0 0" />
    <parent
      link="base_link" />
    <child
      link="neck_pitch_link" />
    <axis
      xyz="0 1 0" />
    <limit
      lower="-1.5707963267949"
      upper="1.5707963267949"
      effort="50"
      velocity="12.5663706143592" />
  </joint>
  <link
    name="neck_yaw_link">
    <inertial>
      <origin
        xyz="0.0383142888831054 0.0963629217693148 0.0159100296711327"
        rpy="0 0 0" />
      <mass
        value="0.682493131271879" />
      <inertia
        ixx="0.00145871306374157"
        ixy="-9.61833046006098E-07"
        ixz="1.54046091886396E-07"
        iyy="0.00337340931472825"
        iyz="4.75649798953562E-06"
        izz="0.00248550353895384" />
    </inertial>
    <visual>
      <origin
        xyz="0 0 0"
        rpy="0 0 0" />
      <geometry>
        <mesh
          filename="package://robot_description/meshes/neck_yaw_link.STL" />
      </geometry>
      <material
        name="">
        <color
          rgba="1 1 1 1" />
      </material>
    </visual>
    <collision>
      <origin
        xyz="0 0 0"
        rpy="0 0 0" />
      <geometry>
        <mesh
          filename="package://robot_description/meshes/neck_yaw_link.STL" />
      </geometry>
    </collision>
  </link>
  <joint
    name="neck_yaw_joint"
    type="revolute">
    <origin
      xyz="-0.0001646 0.10793 -0.0331"
      rpy="0 -1.5708 0" />
    <parent
      link="neck_pitch_link" />
    <child
      link="neck_yaw_link" />
    <axis
      xyz="1 0 0" />
    <limit
      lower="-0.785398163397448"
      upper="1.5707963267949"
      effort="50"
      velocity="12.5663706143592" />
  </joint>
  <link
    name="head_camera_link">
    <inertial>
      <origin
        xyz="-0.0139394698018362 0.00048141789980603 -4.68847183299204E-13"
        rpy="0 0 0" />
      <mass
        value="0.0342115541748522" />
      <inertia
        ixx="2.11830972010361E-05"
        ixy="1.69028050559494E-07"
        ixz="3.16913671446052E-17"
        iyy="6.89707324236642E-06"
        iyz="-1.66683378525437E-17"
        izz="2.56605382132623E-05" />
    </inertial>
    <visual>
      <origin
        xyz="0 0 0"
        rpy="0 0 0" />
      <geometry>
        <mesh
          filename="package://robot_description/meshes/head_camera_link.STL" />
      </geometry>
      <material
        name="">
        <color
          rgba="1 1 1 1" />
      </material>
    </visual>
    <collision>
      <origin
        xyz="0 0 0"
        rpy="0 0 0" />
      <geometry>
        <mesh
          filename="package://robot_description/meshes/head_camera_link.STL" />
      </geometry>
    </collision>
  </link>
  <joint
    name="head_camera_joint"
    type="fixed">
    <origin
      xyz="0.03875 0.14517 -0.021163"
      rpy="0.070416 1.5708 1.6412" />
    <parent
      link="neck_yaw_link" />
    <child
      link="head_camera_link" />
    <axis
      xyz="0 0 0" />
  </joint>
  <link
    name="right_base_pitch_link">
    <inertial>
      <origin
        xyz="-0.00823880685390257 -0.000177429010389696 0.036639888693258"
        rpy="0 0 0" />
      <mass
        value="0.373968361125602" />
      <inertia
        ixx="0.000677688001880238"
        ixy="-2.58441700910704E-06"
        ixz="0.000121708657447633"
        iyy="0.000776630662616677"
        iyz="1.27469892381201E-07"
        izz="0.000778267975793838" />
    </inertial>
    <visual>
      <origin
        xyz="0 0 0"
        rpy="0 0 0" />
      <geometry>
        <mesh
          filename="package://robot_description/meshes/right_base_pitch_link.STL" />
      </geometry>
      <material
        name="">
        <color
          rgba="1 1 1 1" />
      </material>
    </visual>
    <collision>
      <origin
        xyz="0 0 0"
        rpy="0 0 0" />
      <geometry>
        <mesh
          filename="package://robot_description/meshes/right_base_pitch_link.STL" />
      </geometry>
    </collision>
  </link>
  <joint
    name="right_base_pitch_joint"
    type="revolute">
    <origin
      xyz="0 -0.214 0.018"
      rpy="1.5708 0 0" />
    <parent
      link="base_link" />
    <child
      link="right_base_pitch_link" />
    <axis
      xyz="0 0 1" />
    <limit
      lower="-1.83259571459405"
      upper="1.22173047639603"
      effort="50"
      velocity="12.5663706143592" />
  </joint>
  <link
    name="right_shoulder_roll_link">
    <inertial>
      <origin
        xyz="-0.0441322340144276 -1.52001413755709E-06 -0.0590886802780809"
        rpy="0 0 0" />
      <mass
        value="0.34498513448704" />
      <inertia
        ixx="0.000728141508534584"
        ixy="-5.16510754265941E-09"
        ixz="-0.000152571730857858"
        iyy="0.000753829101121134"
        iyz="-6.27798366442623E-08"
        izz="0.000612004295756209" />
    </inertial>
    <visual>
      <origin
        xyz="0 0 0"
        rpy="0 0 0" />
      <geometry>
        <mesh
          filename="package://robot_description/meshes/right_shoulder_roll_link.STL" />
      </geometry>
      <material
        name="">
        <color
          rgba="1 1 1 1" />
      </material>
    </visual>
    <collision>
      <origin
        xyz="0 0 0"
        rpy="0 0 0" />
      <geometry>
        <mesh
          filename="package://robot_description/meshes/right_shoulder_roll_link.STL" />
      </geometry>
    </collision>
  </link>
  <joint
    name="right_shoulder_roll_joint"
    type="revolute">
    <origin
      xyz="0.0513 0 0.07"
      rpy="1.5708 0 1.5708" />
    <parent
      link="right_base_pitch_link" />
    <child
      link="right_shoulder_roll_link" />
    <axis
      xyz="0 0 1" />
    <limit
      lower="-1.5707963267949"
      upper="0.0174532925199433"
      effort="50"
      velocity="12.5663706143592" />
  </joint>
  <link
    name="right_shoulder_yaw_link">
    <inertial>
      <origin
        xyz="-0.02275426608721 -7.17629252346141E-06 0.0347369663347065"
        rpy="0 0 0" />
      <mass
        value="0.12082074165216" />
      <inertia
        ixx="0.000120102514795636"
        ixy="-4.74529810901052E-09"
        ixz="2.56532731551487E-05"
        iyy="0.000151406499021825"
        iyz="-6.15793332040872E-08"
        izz="0.000119212917584518" />
    </inertial>
    <visual>
      <origin
        xyz="0 0 0"
        rpy="0 0 0" />
      <geometry>
        <mesh
          filename="package://robot_description/meshes/right_shoulder_yaw_link.STL" />
      </geometry>
      <material
        name="">
        <color
          rgba="1 1 1 1" />
      </material>
    </visual>
    <collision>
      <origin
        xyz="0 0 0"
        rpy="0 0 0" />
      <geometry>
        <mesh
          filename="package://robot_description/meshes/right_shoulder_yaw_link.STL" />
      </geometry>
    </collision>
  </link>
  <joint
    name="right_shoulder_yaw_joint"
    type="revolute">
    <origin
      xyz="-0.1615 0 -0.0675"
      rpy="1.5708 0 -1.5708" />
    <parent
      link="right_shoulder_roll_link" />
    <child
      link="right_shoulder_yaw_link" />
    <axis
      xyz="0 0 1" />
    <limit
      lower="-2.61799387799149"
      upper="2.61799387799149"
      effort="50"
      velocity="12.5663706143592" />
  </joint>
  <link
    name="right_elbow_pitch_link">
    <inertial>
      <origin
        xyz="-0.000193095363246493 0.0620558225857439 -0.0505800041110315"
        rpy="0 0 0" />
      <mass
        value="0.186598823200443" />
      <inertia
        ixx="0.000147532877768198"
        ixy="1.99649799037027E-07"
        ixz="-2.09879051148464E-06"
        iyy="0.000130976909016118"
        iyz="2.14338643159137E-05"
        izz="0.000109427951636904" />
    </inertial>
    <visual>
      <origin
        xyz="0 0 0"
        rpy="0 0 0" />
      <geometry>
        <mesh
          filename="package://robot_description/meshes/right_elbow_pitch_link.STL" />
      </geometry>
      <material
        name="">
        <color
          rgba="1 1 1 1" />
      </material>
    </visual>
    <collision>
      <origin
        xyz="0 0 0"
        rpy="0 0 0" />
      <geometry>
        <mesh
          filename="package://robot_description/meshes/right_elbow_pitch_link.STL" />
      </geometry>
    </collision>
  </link>
  <joint
    name="right_elbow_pitch_joint"
    type="revolute">
    <origin
      xyz="0.0495 0 0.0625"
      rpy="1.5708 0 1.5708" />
    <parent
      link="right_shoulder_yaw_link" />
    <child
      link="right_elbow_pitch_link" />
    <axis
      xyz="0 0 1" />
    <limit
      lower="-1.5707963267949"
      upper="0.0174532925199433"
      effort="50"
      velocity="12.5663706143592" />
  </joint>
  <link
    name="right_wrist_pitch_link">
    <inertial>
      <origin
        xyz="2.57931114940047E-05 -0.00423112937967962 0.107183604144495"
        rpy="0 0 0" />
      <mass
        value="0.205668000586515" />
      <inertia
        ixx="0.000320178544234312"
        ixy="8.24114464500477E-08"
        ixz="2.75376455749209E-08"
        iyy="0.00030554377450811"
        iyz="3.94553803170522E-05"
        izz="0.000100211946506994" />
    </inertial>
    <visual>
      <origin
        xyz="0 0 0"
        rpy="0 0 0" />
      <geometry>
        <mesh
          filename="package://robot_description/meshes/right_wrist_pitch_link.STL" />
      </geometry>
      <material
        name="">
        <color
          rgba="1 1 1 1" />
      </material>
    </visual>
    <collision>
      <origin
        xyz="0 0 0"
        rpy="0 0 0" />
      <geometry>
        <mesh
          filename="package://robot_description/meshes/right_wrist_pitch_link.STL" />
      </geometry>
    </collision>
  </link>
  <joint
    name="right_wrist_pitch_joint"
    type="revolute">
    <origin
      xyz="0 0.1265 -0.0495"
      rpy="1.5708 0 3.1416" />
    <parent
      link="right_elbow_pitch_link" />
    <child
      link="right_wrist_pitch_link" />
    <axis
      xyz="0 0 1" />
    <limit
      lower="-2.96705972839036"
      upper="2.96705972839036"
      effort="50"
      velocity="12.5663706143592" />
  </joint>
  <link
    name="right_wrist_yaw_link">
    <inertial>
      <origin
        xyz="1.61432639583167E-05 0.0788266958971238 -0.0464968178900581"
        rpy="0 0 0" />
      <mass
        value="0.196343549066047" />
      <inertia
        ixx="0.000126108567693557"
        ixy="1.37575981581003E-07"
        ixz="2.69993050574496E-06"
        iyy="0.000139218410212035"
        iyz="8.16964438280619E-06"
        izz="0.000130892684040908" />
    </inertial>
    <visual>
      <origin
        xyz="0 0 0"
        rpy="0 0 0" />
      <geometry>
        <mesh
          filename="package://robot_description/meshes/right_wrist_yaw_link.STL" />
      </geometry>
      <material
        name="">
        <color
          rgba="1 1 1 1" />
      </material>
    </visual>
    <collision>
      <origin
        xyz="0 0 0"
        rpy="0 0 0" />
      <geometry>
        <mesh
          filename="package://robot_description/meshes/right_wrist_yaw_link.STL" />
      </geometry>
    </collision>
  </link>
  <joint
    name="right_wrist_yaw_joint"
    type="revolute">
    <origin
      xyz="0 0.0415 0.1405"
      rpy="1.5708 0 -3.1416" />
    <parent
      link="right_wrist_pitch_link" />
    <child
      link="right_wrist_yaw_link" />
    <axis
      xyz="0 0 1" />
    <limit
      lower="-2.0943951023932"
      upper="2.0943951023932"
      effort="50"
      velocity="12.5663706143592" />
  </joint>
  <link
    name="right_gripper1_link">
    <inertial>
      <origin
        xyz="-0.0648785249402059 -0.000993464265665378 0.0233298934944725"
        rpy="0 0 0" />
      <mass
        value="0.0375646673398165" />
      <inertia
        ixx="1.97902311156482E-05"
        ixy="8.02076575591093E-08"
        ixz="-2.61476093446484E-06"
        iyy="1.51796634683249E-05"
        iyz="4.68455100212021E-07"
        izz="9.03778878762934E-06" />
    </inertial>
    <visual>
      <origin
        xyz="0 0 0"
        rpy="0 0 0" />
      <geometry>
        <mesh
          filename="package://robot_description/meshes/right_gripper1_link.STL" />
      </geometry>
      <material
        name="">
        <color
          rgba="0.0980392156862745 0.0980392156862745 0.0980392156862745 1" />
      </material>
    </visual>
    <collision>
      <origin
        xyz="0 0 0"
        rpy="0 0 0" />
      <geometry>
        <mesh
          filename="package://robot_description/meshes/right_gripper1_link.STL" />
      </geometry>
    </collision>
  </link>
  <joint
    name="right_gripper1_joint"
    type="prismatic">
    <origin
      xyz="0 0.141000000000003 -0.0424999999999999"
      rpy="1.5707963267949 0 3.14159265358979" />
    <parent
      link="right_wrist_yaw_link" />
    <child
      link="right_gripper1_link" />
    <axis
      xyz="1 0 0" />
    <limit
      lower="0"
      upper="0.03"
      effort="50"
      velocity="20" />
  </joint>
  <link
    name="right_camera_link">
    <inertial>
      <origin
        xyz="0.00305920120943981 0 2.77555756156289E-17"
        rpy="0 0 0" />
      <mass
        value="0.00553667243699105" />
      <inertia
        ixx="7.6927000981648E-07"
        ixy="6.94831714544543E-23"
        ixz="1.14978105144871E-22"
        iyy="5.44604723458135E-07"
        iyz="6.61744490042422E-22"
        izz="5.44604723458134E-07" />
    </inertial>
    <visual>
      <origin
        xyz="0 0 0"
        rpy="0 0 0" />
      <geometry>
        <mesh
          filename="package://robot_description/meshes/right_camera_link.STL" />
      </geometry>
      <material
        name="">
        <color
          rgba="1 1 1 1" />
      </material>
    </visual>
    <collision>
      <origin
        xyz="0 0 0"
        rpy="0 0 0" />
      <geometry>
        <mesh
          filename="package://robot_description/meshes/right_camera_link.STL" />
      </geometry>
    </collision>
  </link>
  <joint
    name="right_camera_joint"
    type="fixed">
    <origin
      xyz="0 0.072 -0.1565"
      rpy="1.5708 0 1.5708" />
    <parent
      link="right_wrist_yaw_link" />
    <child
      link="right_camera_link" />
    <axis
      xyz="0 0 0" />
  </joint>
  <link
    name="right_gripper2_link">
    <inertial>
      <origin
        xyz="0.064878478730105 0.000993422702135982 0.0233301213792956"
        rpy="0 0 0" />
      <mass
        value="0.0375648370970392" />
      <inertia
        ixx="1.9791258171854E-05"
        ixy="8.0210620504891E-08"
        ixz="2.61494924156235E-06"
        iyy="1.51805727189142E-05"
        iyz="-4.68431658773564E-07"
        izz="9.03801190104317E-06" />
    </inertial>
    <visual>
      <origin
        xyz="0 0 0"
        rpy="0 0 0" />
      <geometry>
        <mesh
          filename="package://robot_description/meshes/right_gripper2_link.STL" />
      </geometry>
      <material
        name="">
        <color
          rgba="0.0980392156862745 0.0980392156862745 0.0980392156862745 1" />
      </material>
    </visual>
    <collision>
      <origin
        xyz="0 0 0"
        rpy="0 0 0" />
      <geometry>
        <mesh
          filename="package://robot_description/meshes/right_gripper2_link.STL" />
      </geometry>
    </collision>
  </link>
  <joint
    name="right_gripper2_joint"
    type="prismatic">
    <origin
      xyz="0 0.141 -0.0425"
      rpy="1.5708 0 3.1416" />
    <parent
      link="right_wrist_yaw_link" />
    <child
      link="right_gripper2_link" />
    <axis
      xyz="1 0 0" />
    <mimic joint="right_gripper1_joint" multiplier="-1.0" />
    <limit
      lower="-0.03"
      upper="0"
      effort="50"
      velocity="20" />
  </joint>
  <link
    name="left_base_pitch_link">
    <inertial>
      <origin
        xyz="-0.0082388068543495 0.000196285390288709 0.0366332365271437"
        rpy="0 0 0" />
      <mass
        value="0.373968361140818" />
      <inertia
        ixx="0.000677688001880296"
        ixy="2.58441760599191E-06"
        ixz="0.000121708657236937"
        iyy="0.000774384013481784"
        iyz="-2.91538328272566E-06"
        izz="0.00078051462492885" />
    </inertial>
    <visual>
      <origin
        xyz="0 0 0"
        rpy="0 0 0" />
      <geometry>
        <mesh
          filename="package://robot_description/meshes/left_base_pitch_link.STL" />
      </geometry>
      <material
        name="">
        <color
          rgba="1 1 1 1" />
      </material>
    </visual>
    <collision>
      <origin
        xyz="0 0 0"
        rpy="0 0 0" />
      <geometry>
        <mesh
          filename="package://robot_description/meshes/left_base_pitch_link.STL" />
      </geometry>
    </collision>
  </link>
  <joint
    name="left_base_pitch_joint"
    type="revolute">
    <origin
      xyz="0 0.214 0.018"
      rpy="-1.5708 0 0" />
    <parent
      link="base_link" />
    <child
      link="left_base_pitch_link" />
    <axis
      xyz="0 0 1" />
    <limit
      lower="-1.22173047639603"
      upper="1.83259571459405"
      effort="50"
      velocity="12.5663706143592" />
  </joint>
  <link
    name="left_shoulder_roll_link">
    <inertial>
      <origin
        xyz="0.0441326608815154 -1.68304018899335E-06 -0.0590936346655853"
        rpy="0 0 0" />
      <mass
        value="0.344985134468612" />
      <inertia
        ixx="0.000728141508532383"
        ixy="5.14066605231708E-09"
        ixz="0.000152561992523525"
        iyy="0.000753829727505475"
        iyz="6.20072335765447E-08"
        izz="0.000612003669369676" />
    </inertial>
    <visual>
      <origin
        xyz="0 0 0"
        rpy="0 0 0" />
      <geometry>
        <mesh
          filename="package://robot_description/meshes/left_shoulder_roll_link.STL" />
      </geometry>
      <material
        name="">
        <color
          rgba="1 1 1 1" />
      </material>
    </visual>
    <collision>
      <origin
        xyz="0 0 0"
        rpy="0 0 0" />
      <geometry>
        <mesh
          filename="package://robot_description/meshes/left_shoulder_roll_link.STL" />
      </geometry>
    </collision>
  </link>
  <joint
    name="left_shoulder_roll_joint"
    type="revolute">
    <origin
      xyz="0.0513 0 0.07"
      rpy="1.5708 0 1.5708" />
    <parent
      link="left_base_pitch_link" />
    <child
      link="left_shoulder_roll_link" />
    <axis
      xyz="0 0 1" />
    <limit
      lower="-0.0174532925199433"
      upper="1.5707963267949"
      effort="50"
      velocity="12.5663706143592" />
  </joint>
  <link
    name="left_shoulder_yaw_link">
    <inertial>
      <origin
        xyz="0.0227542762867688 -9.96244599593687E-07 0.0347409464850744"
        rpy="0 0 0" />
      <mass
        value="0.120820726215317" />
      <inertia
        ixx="0.000120102502009151"
        ixy="-6.48129556622318E-09"
        ixz="-2.56609600931017E-05"
        iyy="0.000151494553191428"
        iyz="-9.891134151716E-08"
        izz="0.000119124848970856" />
    </inertial>
    <visual>
      <origin
        xyz="0 0 0"
        rpy="0 0 0" />
      <geometry>
        <mesh
          filename="package://robot_description/meshes/left_shoulder_yaw_link.STL" />
      </geometry>
      <material
        name="">
        <color
          rgba="1 1 1 1" />
      </material>
    </visual>
    <collision>
      <origin
        xyz="0 0 0"
        rpy="0 0 0" />
      <geometry>
        <mesh
          filename="package://robot_description/meshes/left_shoulder_yaw_link.STL" />
      </geometry>
    </collision>
  </link>
  <joint
    name="left_shoulder_yaw_joint"
    type="revolute">
    <origin
      xyz="0.1615 0 -0.0675"
      rpy="1.5708 0 1.5708" />
    <parent
      link="left_shoulder_roll_link" />
    <child
      link="left_shoulder_yaw_link" />
    <axis
      xyz="0 0 1" />
    <limit
      lower="-2.61799387799149"
      upper="2.61799387799149"
      effort="50"
      velocity="12.5663706143592" />
  </joint>
  <link
    name="left_elbow_pitch_link">
    <inertial>
      <origin
        xyz="0.000222684109330573 0.0620557929723517 -0.0506455512443044"
        rpy="0 0 0" />
      <mass
        value="0.186600373061323" />
      <inertia
        ixx="0.000147447617441775"
        ixy="-1.85989373355161E-08"
        ixz="2.17203131414604E-06"
        iyy="0.000130974751830717"
        iyz="2.10363300303337E-05"
        izz="0.000109511560291374" />
    </inertial>
    <visual>
      <origin
        xyz="0 0 0"
        rpy="0 0 0" />
      <geometry>
        <mesh
          filename="package://robot_description/meshes/left_elbow_pitch_link.STL" />
      </geometry>
      <material
        name="">
        <color
          rgba="1 1 1 1" />
      </material>
    </visual>
    <collision>
      <origin
        xyz="0 0 0"
        rpy="0 0 0" />
      <geometry>
        <mesh
          filename="package://robot_description/meshes/left_elbow_pitch_link.STL" />
      </geometry>
    </collision>
  </link>
  <joint
    name="left_elbow_pitch_joint"
    type="revolute">
    <origin
      xyz="-0.0495 0 0.0625"
      rpy="1.5708 0 -1.5708" />
    <parent
      link="left_shoulder_yaw_link" />
    <child
      link="left_elbow_pitch_link" />
    <axis
      xyz="0 0 1" />
    <limit
      lower="-0.0174532925199433"
      upper="1.5707963267949"
      effort="50"
      velocity="12.5663706143592" />
  </joint>
  <link
    name="left_wrist_pitch_link">
    <inertial>
      <origin
        xyz="4.16022889050821E-05 0.00423127490096759 0.107266428473007"
        rpy="0 0 0" />
      <mass
        value="0.205667966182894" />
      <inertia
        ixx="0.000320146396047363"
        ixy="-1.77524168089713E-07"
        ixz="-5.30662636505188E-08"
        iyy="0.000305543651844278"
        iyz="-3.99606241008235E-05"
        izz="0.000100243964692397" />
    </inertial>
    <visual>
      <origin
        xyz="0 0 0"
        rpy="0 0 0" />
      <geometry>
        <mesh
          filename="package://robot_description/meshes/left_wrist_pitch_link.STL" />
      </geometry>
      <material
        name="">
        <color
          rgba="1 1 1 1" />
      </material>
    </visual>
    <collision>
      <origin
        xyz="0 0 0"
        rpy="0 0 0" />
      <geometry>
        <mesh
          filename="package://robot_description/meshes/left_wrist_pitch_link.STL" />
      </geometry>
    </collision>
  </link>
  <joint
    name="left_wrist_pitch_joint"
    type="revolute">
    <origin
      xyz="0 0.1265 -0.0495"
      rpy="-1.5708 0 0" />
    <parent
      link="left_elbow_pitch_link" />
    <child
      link="left_wrist_pitch_link" />
    <axis
      xyz="0 0 1" />
    <limit
      lower="-2.96705972839036"
      upper="2.96705972839036"
      effort="50"
      velocity="12.5663706143592" />
  </joint>
  <link
    name="left_wrist_yaw_link">
    <inertial>
      <origin
        xyz="1.62497954153407E-05 -0.0788268714792976 0.0464967944548998"
        rpy="0 0 0" />
      <mass
        value="0.196343643347946" />
      <inertia
        ixx="0.00012610829120133"
        ixy="-1.37587722732548E-07"
        ixz="-2.70021943553872E-06"
        iyy="0.000139218164526277"
        iyz="8.16958038209142E-06"
        izz="0.000130892785783919" />
    </inertial>
    <visual>
      <origin
        xyz="0 0 0"
        rpy="0 0 0" />
      <geometry>
        <mesh
          filename="package://robot_description/meshes/left_wrist_yaw_link.STL" />
      </geometry>
      <material
        name="">
        <color
          rgba="1 1 1 1" />
      </material>
    </visual>
    <collision>
      <origin
        xyz="0 0 0"
        rpy="0 0 0" />
      <geometry>
        <mesh
          filename="package://robot_description/meshes/left_wrist_yaw_link.STL" />
      </geometry>
    </collision>
  </link>
  <joint
    name="left_wrist_yaw_joint"
    type="revolute">
    <origin
      xyz="0 -0.0415 0.1405"
      rpy="-1.5708 0 0" />
    <parent
      link="left_wrist_pitch_link" />
    <child
      link="left_wrist_yaw_link" />
    <axis
      xyz="0 0 -1" />
    <limit
      lower="-2.0943951023932"
      upper="2.0943951023932"
      effort="50"
      velocity="12.5663706143592" />
  </joint>
  <link
    name="left_gripper1_link">
    <inertial>
      <origin
        xyz="-0.0648785249788183 -0.000993464182677262 0.0233298932977575"
        rpy="0 0 0" />
      <mass
        value="0.0375646671073411" />
      <inertia
        ixx="1.97902309383175E-05"
        ixy="8.0207637278807E-08"
        ixz="2.61476091678011E-06"
        iyy="1.51796633456735E-05"
        iyz="-4.68455009458741E-07"
        izz="9.03778873731568E-06" />
    </inertial>
    <visual>
      <origin
        xyz="0 0 0"
        rpy="0 0 0" />
      <geometry>
        <mesh
          filename="package://robot_description/meshes/left_gripper1_link.STL" />
      </geometry>
      <material
        name="">
        <color
          rgba="0.0980392156862745 0.0980392156862745 0.0980392156862745 1" />
      </material>
    </visual>
    <collision>
      <origin
        xyz="0 0 0"
        rpy="0 0 0" />
      <geometry>
        <mesh
          filename="package://robot_description/meshes/left_gripper1_link.STL" />
      </geometry>
    </collision>
  </link>
  <joint
    name="left_gripper1_joint"
    type="prismatic">
    <origin
      xyz="0 -0.14099995082628 0.0425000000000004"
      rpy="-1.5707963267949 0 3.14159265358979" />
    <parent
      link="left_wrist_yaw_link" />
    <child
      link="left_gripper1_link" />
    <axis
      xyz="-1 0 0" />
    <limit
      lower="0"
      upper="0.03"
      effort="50"
      velocity="20" />
  </joint>
  <link
    name="left_camera_link">
    <inertial>
      <origin
        xyz="0.00305920120943992 -2.77555756156289E-17 0"
        rpy="0 0 0" />
      <mass
        value="0.00553667243699105" />
      <inertia
        ixx="7.69270009816479E-07"
        ixy="-5.54211010410529E-23"
        ixz="-4.35097002202893E-22"
        iyy="5.44604723458134E-07"
        iyz="-6.22039820639877E-22"
        izz="5.44604723458134E-07" />
    </inertial>
    <visual>
      <origin
        xyz="0 0 0"
        rpy="0 0 0" />
      <geometry>
        <mesh
          filename="package://robot_description/meshes/left_camera_link.STL" />
      </geometry>
      <material
        name="">
        <color
          rgba="1 1 1 1" />
      </material>
    </visual>
    <collision>
      <origin
        xyz="0 0 0"
        rpy="0 0 0" />
      <geometry>
        <mesh
          filename="package://robot_description/meshes/left_camera_link.STL" />
      </geometry>
    </collision>
  </link>
  <joint
    name="left_camera_joint"
    type="fixed">
    <origin
      xyz="0 -0.072 0.1565"
      rpy="0 0 -1.5708" />
    <parent
      link="left_wrist_yaw_link" />
    <child
      link="left_camera_link" />
    <axis
      xyz="0 0 0" />
  </joint>
  <link
    name="left_gripper2_link">
    <inertial>
      <origin
        xyz="-0.0648784787032854 -0.000993422755843354 0.0233301215451982"
        rpy="0 0 0" />
      <mass
        value="0.0375648373217044" />
      <inertia
        ixx="1.97912583223621E-05"
        ixy="8.02106418958551E-08"
        ixz="-2.61494926081506E-06"
        iyy="1.51805728297286E-05"
        iyz="4.68431735136251E-07"
        izz="9.0380119445294E-06" />
    </inertial>
    <visual>
      <origin
        xyz="0 0 0"
        rpy="0 0 0" />
      <geometry>
        <mesh
          filename="package://robot_description/meshes/left_gripper2_link.STL" />
      </geometry>
      <material
        name="">
        <color
          rgba="0.0980392156862745 0.0980392156862745 0.0980392156862745 1" />
      </material>
    </visual>
    <collision>
      <origin
        xyz="0 0 0"
        rpy="0 0 0" />
      <geometry>
        <mesh
          filename="package://robot_description/meshes/left_gripper2_link.STL" />
      </geometry>
    </collision>
  </link>
  <joint
    name="left_gripper2_joint"
    type="prismatic">
    <origin
      xyz="0 -0.141 0.0425"
      rpy="-1.5708 0 3.1416" />
    <parent
      link="left_wrist_yaw_link" />
    <child
      link="left_gripper2_link" />
    <axis
      xyz="-1 0 0" />
    <mimic joint="left_gripper1_joint" multiplier="-1.0" />
    <limit
      lower="-0.03"
      upper="0"
      effort="50"
      velocity="20" />
  </joint>

    <!-- 右手机械臂末端工具系坐标系 -->
    <link name="right_tcp_link" />
    <joint
        name="right_tcp_joint"
        type="fixed">
        <origin
            xyz="0 0.141000000000003 -0.0424999999999999"
            rpy="1.5707963267949 0 3.14159265358979" />
        <parent link="right_wrist_yaw_link" />
        <child link="right_tcp_link"/>
    </joint>
    
    <!-- 左手机械臂末端工具系坐标系 -->
    <link name="left_tcp_link" />
    <joint
        name="left_tcp_joint"
        type="fixed">
        <origin
            xyz="0 -0.14099995082628 0.0425000000000004"
            rpy="-1.5707963267949 0 3.14159265358979" />
        <parent link="left_wrist_yaw_link" />     
        <child link="left_tcp_link"/>
    </joint>

</robot>
