<mujoco model="humanoid_right_arm">
  <compiler angle="radian" coordinate="local" meshdir="../robot_description/meshes" autolimits="true"/>
  <option timestep="0.004" gravity="0 0 -9.81" integrator="implicitfast" cone="elliptic"/>
  <visual>
    <headlight ambient="0.55 0.55 0.55" diffuse="0.4 0.4 0.4" specular="0.1 0.1 0.1"/>
    <rgba haze="0.15 0.2 0.25 1"/>
  </visual>
  <default>
    <default class="visual">
      <geom group="1" type="mesh" contype="0" conaffinity="0"/>
    </default>
    <default class="collision">
      <geom group="3" density="900"/>
    </default>
  </default>
  <asset>
    <mesh name="base_link_mesh" file="base_link.STL"/>
    <mesh name="right_base_pitch_link_mesh" file="right_base_pitch_link.STL"/>
    <mesh name="right_shoulder_roll_link_mesh" file="right_shoulder_roll_link.STL"/>
    <mesh name="right_shoulder_yaw_link_mesh" file="right_shoulder_yaw_link.STL"/>
    <mesh name="right_elbow_pitch_link_mesh" file="right_elbow_pitch_link.STL"/>
    <mesh name="right_wrist_pitch_link_mesh" file="right_wrist_pitch_link.STL"/>
    <mesh name="right_wrist_yaw_link_mesh" file="right_wrist_yaw_link.STL"/>
    <mesh name="right_gripper1_link_mesh" file="right_gripper1_link.STL"/>
    <mesh name="right_gripper2_link_mesh" file="right_gripper2_link.STL"/>
  </asset>
  <worldbody>
    <light name="sun" pos="0 0 2.4" dir="0 0 -1" directional="true"/>
    <camera name="overview" pos="1.25 -1.1 1.35" xyaxes="0.72 0.69 0 -0.35 0.36 0.86"/>
    <geom name="ground" type="plane" size="2 2 0.1" rgba="0.92 0.94 0.96 1" friction="1 0.1 0.01"/>
    <geom name="table" type="box" pos="0.28 0.30 0.725" size="0.25 0.20 0.025" rgba="0.60 0.44 0.32 1" friction="1.1 0.05 0.01"/>
    <body name="brick" pos="0.28 0.27 0.77">
      <freejoint name="brick_freejoint"/>
      <geom name="brick_geom" type="box" size="0.02 0.01 0.01" mass="0.08" friction="1.2 0.02 0.002" rgba="0.85 0.25 0.18 1"/>
      <site name="brick_site" type="sphere" size="0.008" rgba="1 1 0 1"/>
    </body>
    <body name="base_link" pos="0 0 0.6">
      <inertial pos="1.07784451355147E-06 0.0284280497758001 0.0930501056429116" mass="25.2827775843096" fullinertia="1.05306308303982 0.379347819173407 1.39119566760917 5.35850857338871E-07 -8.40544864225828E-06 4.4668154477851E-06"/>
      <geom name="base_link_visual" type="mesh" mesh="base_link_mesh" contype="0" conaffinity="0" group="1" rgba="0.9 0.9 0.9 1"/>
      <geom name="base_collision" type="box" pos="0 0.03 0.09" size="0.16 0.11 0.16" rgba="0.7 0.75 0.82 1"/>
      <body name="right_base_pitch_link" pos="0.21400441954841 0.189998253900819 0.822999049601032" euler="1.5707963267949 0 1.5707963267949">
        <joint name="right_base_pitch_joint" type="hinge" axis="0 0 -1" range="-1.6 1.6" damping="3.0" armature="0.02" limited="true"/>
        <inertial pos="-0.0394540906091678 -0.00117049156839028 0.0362772096702395" mass="0.244817289982652" fullinertia="0.00042258611468929 0.00043362815715413 0.000449580199614448 -3.33213778042763E-07 6.13148868322963E-05 1.84861840406614E-06"/>
        <geom name="right_base_pitch_link_visual" type="mesh" mesh="right_base_pitch_link_mesh" contype="0" conaffinity="0" group="1" rgba="0.9 0.9 0.9 1"/>
        <geom name="right_base_pitch_collision" type="capsule" fromto="0 0 0 -0.12 0 0.08" size="0.055" rgba="0.8 0.8 0.8 1"/>
        <body name="right_shoulder_roll_link" pos="0.0512767086241353 0.00154568843845215 0.070000086877735" euler="1.57079632679489 -0.0124370994640314 1.60093654227117">
          <joint name="right_shoulder_roll_joint" type="hinge" axis="0 0 -1" range="-1.4 1.4" damping="3.0" armature="0.02" limited="true"/>
          <inertial pos="-0.0504751969032359 -2.3505993093087E-06 -0.0382593125478601" mass="0.219562602027133" fullinertia="0.000414250305228579 0.000412104091228023 0.000365288665382115 -5.1544201930132E-09 -8.79018796006794E-05 -6.24422590434745E-08"/>
          <geom name="right_shoulder_roll_link_visual" type="mesh" mesh="right_shoulder_roll_link_mesh" contype="0" conaffinity="0" group="1" rgba="0.9 0.9 0.9 1"/>
          <geom name="right_shoulder_roll_collision" type="capsule" fromto="0 0 0 -0.15 0 -0.06" size="0.045" rgba="0.8 0.8 0.8 1"/>
          <body name="right_shoulder_yaw_link" pos="-0.161499730454391 0 -0.0674997882054564" euler="1.5707963267949 -0.209915812016821 -1.5707963267949">
            <joint name="right_shoulder_yaw_joint" type="hinge" axis="0 0 1" range="-1.8 1.8" damping="3.0" armature="0.02" limited="true"/>
            <inertial pos="-0.020385273211367 -8.15235141520682E-06 0.0357353445479509" mass="0.106143604615312" fullinertia="9.66386839936161E-05 0.000122064598284769 0.00010313012003071 -4.74531869270227E-09 2.12882628388833E-05 -6.1579299009481E-08"/>
            <geom name="right_shoulder_yaw_link_visual" type="mesh" mesh="right_shoulder_yaw_link_mesh" contype="0" conaffinity="0" group="1" rgba="0.9 0.9 0.9 1"/>
            <geom name="right_shoulder_yaw_collision" type="capsule" fromto="0 0 0 0.0 0.07 -0.10" size="0.04" rgba="0.8 0.8 0.8 1"/>
            <body name="right_elbow_pitch_link" pos="0.0495000377373268 0 0.0624999168897828" euler="1.5707963267949 0.00263601886731738 1.5707963267949">
              <joint name="right_elbow_pitch_joint" type="hinge" axis="-0.333848242516012 0.0592718558412337 0.940761499039" range="-2.0 2.0" damping="3.0" armature="0.02" limited="true"/>
              <inertial pos="-3.42841572391756E-05 0.0729459113904672 -0.0410111671034344" mass="0.154099206711241" fullinertia="8.75612800169932E-05 8.00343513136428E-05 7.60282435942892E-05 -8.24914993394397E-08 2.8611763084907E-08 9.62612120488893E-06"/>
              <geom name="right_elbow_pitch_link_visual" type="mesh" mesh="right_elbow_pitch_link_mesh" contype="0" conaffinity="0" group="1" rgba="0.9 0.9 0.9 1"/>
              <geom name="right_elbow_pitch_collision" type="capsule" fromto="0 0 0 0.0 0.12 -0.05" size="0.032" rgba="0.8 0.8 0.8 1"/>
              <body name="right_wrist_pitch_link" pos="0 0.126500083668823 -0.0495002104136634" euler="1.5707963267949 0.208003209624867 3.14159265358979">
                <joint name="right_wrist_pitch_joint" type="hinge" axis="0 0 -1" range="-1.8 1.8" damping="3.0" armature="0.02" limited="true"/>
                <inertial pos="2.75788182445003E-05 -0.000871878112892799 0.104186529687359" mass="0.192205595442942" fullinertia="0.000302459654412395 0.00028537077989617 9.91159076780823E-05 8.24266800328281E-08 2.75449341259816E-08 3.77471294040012E-05"/>
                <geom name="right_wrist_pitch_link_visual" type="mesh" mesh="right_wrist_pitch_link_mesh" contype="0" conaffinity="0" group="1" rgba="0.9 0.9 0.9 1"/>
                <geom name="right_wrist_pitch_collision" type="capsule" fromto="0 0 0 0.0 0.04 0.11" size="0.028" rgba="0.8 0.8 0.8 1"/>
                <body name="right_wrist_yaw_link" pos="0 0.0414999999999797 0.140500210413661" euler="1.5707963267949 0.575197538261195 3.14159265358979">
                  <joint name="right_wrist_yaw_joint" type="hinge" axis="0 0 -1" range="-2.5 2.5" damping="3.0" armature="0.02" limited="true"/>
                  <inertial pos="7.27612933126079E-05 0.0809191230537369 -0.0386606819862753" mass="0.175438598998815" fullinertia="9.6324565447174E-05 0.000109953050418614 0.000125124839716495 1.37624512021152E-07 2.89958169269242E-06 5.03326002219079E-06"/>
                  <geom name="right_wrist_yaw_link_visual" type="mesh" mesh="right_wrist_yaw_link_mesh" contype="0" conaffinity="0" group="1" rgba="0.9 0.9 0.9 1"/>
                  <geom name="right_wrist_yaw_collision" type="capsule" fromto="0 0 0 0.0 0.12 -0.03" size="0.026" rgba="0.8 0.8 0.8 1"/>
                  <site name="ee_site" type="sphere" pos="0 0.145 0.024" size="0.012" rgba="1 0 0 1"/>
                  <site name="grasp_target_site" type="sphere" pos="0 0.165 0.024" size="0.008" rgba="0 1 0 1"/>
                  <body name="right_gripper1_link" pos="0 0.141000000000003 -0.0424999999999999" euler="1.5707963267949 0 3.14159265358979">
                    <joint name="right_gripper1_joint" type="slide" axis="1 0 0" range="0.0 0.028" damping="1.0" armature="0.001" limited="true"/>
                    <inertial pos="-0.0594271349448385 -0.0021592700647648 0.0242071304277063" mass="0.0358339207664623" fullinertia="1.96900849491953E-05 1.51820051704718E-05 8.95629031357462E-06 1.49577745788164E-07 -2.61611297419697E-06 4.68868627254808E-07"/>
                    <geom name="right_gripper1_link_visual" type="mesh" mesh="right_gripper1_link_mesh" contype="0" conaffinity="0" group="1" rgba="0.9 0.9 0.9 1"/>
                    <geom name="finger_left_pad" type="box" pos="-0.055 0 0.024" size="0.035 0.008 0.012" friction="1.5 0.02 0.001" rgba="0.15 0.15 0.15 1"/>
                  </body>
                  <body name="right_gripper2_link" pos="0 0.141000000000003 -0.0424999999999999" euler="1.5707963267949 0 3.14159265358979">
                    <joint name="right_gripper2_joint" type="slide" axis="1 0 0" range="-0.028 0.0" damping="1.0" armature="0.001" limited="true"/>
                    <inertial pos="0.0596503865175193 0.0019659579201895 0.0221271099610874" mass="0.0393551869062514" fullinertia="1.98397159910276E-05 1.54499686755966E-05 9.3435573957773E-06 1.49583238832345E-07 2.6160400152461E-06 -4.68723727640429E-07"/>
                    <geom name="right_gripper2_link_visual" type="mesh" mesh="right_gripper2_link_mesh" contype="0" conaffinity="0" group="1" rgba="0.9 0.9 0.9 1"/>
                    <geom name="finger_right_pad" type="box" pos="0.055 0 0.024" size="0.035 0.008 0.012" friction="1.5 0.02 0.001" rgba="0.15 0.15 0.15 1"/>
                  </body>
                </body>
              </body>
            </body>
          </body>
        </body>
      </body>
    </body>
  </worldbody>
  <actuator>
    <position name="right_base_pitch_joint_act" joint="right_base_pitch_joint" kp="80" ctrlrange="-1.6 1.6" forcelimited="false"/>
    <position name="right_shoulder_roll_joint_act" joint="right_shoulder_roll_joint" kp="80" ctrlrange="-1.4 1.4" forcelimited="false"/>
    <position name="right_shoulder_yaw_joint_act" joint="right_shoulder_yaw_joint" kp="70" ctrlrange="-1.8 1.8" forcelimited="false"/>
    <position name="right_elbow_pitch_joint_act" joint="right_elbow_pitch_joint" kp="70" ctrlrange="-2.0 2.0" forcelimited="false"/>
    <position name="right_wrist_pitch_joint_act" joint="right_wrist_pitch_joint" kp="40" ctrlrange="-1.8 1.8" forcelimited="false"/>
    <position name="right_wrist_yaw_joint_act" joint="right_wrist_yaw_joint" kp="35" ctrlrange="-2.5 2.5" forcelimited="false"/>
    <position name="right_gripper1_joint_act" joint="right_gripper1_joint" kp="250" ctrlrange="0.0 0.028" forcelimited="false"/>
    <position name="right_gripper2_joint_act" joint="right_gripper2_joint" kp="250" ctrlrange="-0.028 0.0" forcelimited="false"/>
  </actuator>
  <keyframe>
    <key name="home" qpos="0 0 0 0 0 0 0.025 -0.025 0.28 0.27 0.77 1 0 0 0"/>
  </keyframe>
</mujoco>
